[2024-09-09T15:44:55.546+0000] {local_task_job_runner.py:120} INFO - ::group::Pre task execution logs
[2024-09-09T15:44:55.575+0000] {taskinstance.py:2076} INFO - Dependencies all met for dep_context=non-requeueable deps ti=<TaskInstance: product_etl_dag.extract_dimProudcts_load.get_src_tables scheduled__2024-09-08T09:00:00+00:00 [queued]>
[2024-09-09T15:44:55.584+0000] {taskinstance.py:2076} INFO - Dependencies all met for dep_context=requeueable deps ti=<TaskInstance: product_etl_dag.extract_dimProudcts_load.get_src_tables scheduled__2024-09-08T09:00:00+00:00 [queued]>
[2024-09-09T15:44:55.584+0000] {taskinstance.py:2306} INFO - Starting attempt 1 of 1
[2024-09-09T15:44:55.601+0000] {taskinstance.py:2330} INFO - Executing <Task(_PythonDecoratedOperator): extract_dimProudcts_load.get_src_tables> on 2024-09-08 09:00:00+00:00
[2024-09-09T15:44:55.608+0000] {warnings.py:112} WARNING - /home/***/.local/lib/python3.12/site-packages/***/task/task_runner/standard_task_runner.py:62: DeprecationWarning: This process (pid=180) is multi-threaded, use of fork() may lead to deadlocks in the child.
  pid = os.fork()

[2024-09-09T15:44:55.610+0000] {standard_task_runner.py:64} INFO - Started process 182 to run task
[2024-09-09T15:44:55.610+0000] {standard_task_runner.py:90} INFO - Running: ['***', 'tasks', 'run', 'product_etl_dag', 'extract_dimProudcts_load.get_src_tables', 'scheduled__2024-09-08T09:00:00+00:00', '--job-id', '26', '--raw', '--subdir', 'DAGS_FOLDER/etl_dag.py', '--cfg-path', '/tmp/tmp7wk6k9h7']
[2024-09-09T15:44:55.611+0000] {standard_task_runner.py:91} INFO - Job 26: Subtask extract_dimProudcts_load.get_src_tables
[2024-09-09T15:44:55.663+0000] {task_command.py:426} INFO - Running <TaskInstance: product_etl_dag.extract_dimProudcts_load.get_src_tables scheduled__2024-09-08T09:00:00+00:00 [running]> on host a2fa5cf8945b
[2024-09-09T15:44:55.761+0000] {taskinstance.py:2648} INFO - Exporting env vars: AIRFLOW_CTX_DAG_OWNER='***' AIRFLOW_CTX_DAG_ID='product_etl_dag' AIRFLOW_CTX_TASK_ID='extract_dimProudcts_load.get_src_tables' AIRFLOW_CTX_EXECUTION_DATE='2024-09-08T09:00:00+00:00' AIRFLOW_CTX_TRY_NUMBER='1' AIRFLOW_CTX_DAG_RUN_ID='scheduled__2024-09-08T09:00:00+00:00'
[2024-09-09T15:44:55.763+0000] {taskinstance.py:430} INFO - ::endgroup::
[2024-09-09T15:44:55.774+0000] {base.py:84} INFO - Using connection ID 'sqlserver' for task execution.
[2024-09-09T15:45:16.807+0000] {taskinstance.py:441} INFO - ::group::Post task execution logs
[2024-09-09T15:45:16.808+0000] {taskinstance.py:2905} ERROR - Task failed with exception
Traceback (most recent call last):
  File "src/pymssql/_pymssql.pyx", line 650, in pymssql._pymssql.connect
  File "src/pymssql/_mssql.pyx", line 2155, in pymssql._mssql.connect
  File "src/pymssql/_mssql.pyx", line 712, in pymssql._mssql.MSSQLConnection.__init__
  File "src/pymssql/_mssql.pyx", line 1881, in pymssql._mssql.maybe_raise_MSSQLDatabaseException
  File "src/pymssql/_mssql.pyx", line 1898, in pymssql._mssql.raise_MSSQLDatabaseException
pymssql._mssql.MSSQLDatabaseException: (20009, b'DB-Lib error message 20009, severity 9:\nUnable to connect: Adaptive Server is unavailable or does not exist (192.168.1.228)\nNet-Lib error during Connection refused (111)\nDB-Lib error message 20009, severity 9:\nUnable to connect: Adaptive Server is unavailable or does not exist (192.168.1.228)\nNet-Lib error during Connection refused (111)\n')

During handling of the above exception, another exception occurred:

Traceback (most recent call last):
  File "/home/airflow/.local/lib/python3.12/site-packages/airflow/models/taskinstance.py", line 465, in _execute_task
    result = _execute_callable(context=context, **execute_callable_kwargs)
             ^^^^^^^^^^^^^^^^^^^^^^^^^^^^^^^^^^^^^^^^^^^^^^^^^^^^^^^^^^^^^
  File "/home/airflow/.local/lib/python3.12/site-packages/airflow/models/taskinstance.py", line 432, in _execute_callable
    return execute_callable(context=context, **execute_callable_kwargs)
           ^^^^^^^^^^^^^^^^^^^^^^^^^^^^^^^^^^^^^^^^^^^^^^^^^^^^^^^^^^^^
  File "/home/airflow/.local/lib/python3.12/site-packages/airflow/models/baseoperator.py", line 401, in wrapper
    return func(self, *args, **kwargs)
           ^^^^^^^^^^^^^^^^^^^^^^^^^^^
  File "/home/airflow/.local/lib/python3.12/site-packages/airflow/decorators/base.py", line 265, in execute
    return_value = super().execute(context)
                   ^^^^^^^^^^^^^^^^^^^^^^^^
  File "/home/airflow/.local/lib/python3.12/site-packages/airflow/models/baseoperator.py", line 401, in wrapper
    return func(self, *args, **kwargs)
           ^^^^^^^^^^^^^^^^^^^^^^^^^^^
  File "/home/airflow/.local/lib/python3.12/site-packages/airflow/operators/python.py", line 235, in execute
    return_value = self.execute_callable()
                   ^^^^^^^^^^^^^^^^^^^^^^^
  File "/home/airflow/.local/lib/python3.12/site-packages/airflow/operators/python.py", line 252, in execute_callable
    return self.python_callable(*self.op_args, **self.op_kwargs)
           ^^^^^^^^^^^^^^^^^^^^^^^^^^^^^^^^^^^^^^^^^^^^^^^^^^^^^
  File "/opt/airflow/dags/etl_dag.py", line 17, in get_src_tables
    df = hook.get_pandas_df(sql)
         ^^^^^^^^^^^^^^^^^^^^^^^
  File "/home/airflow/.local/lib/python3.12/site-packages/airflow/providers/common/sql/hooks/sql.py", line 268, in get_pandas_df
    with closing(self.get_conn()) as conn:
                 ^^^^^^^^^^^^^^^
  File "/home/airflow/.local/lib/python3.12/site-packages/airflow/providers/microsoft/mssql/hooks/mssql.py", line 162, in get_conn
    return pymssql.connect(
           ^^^^^^^^^^^^^^^^
  File "src/pymssql/_pymssql.pyx", line 659, in pymssql._pymssql.connect
pymssql.exceptions.OperationalError: (20009, b'DB-Lib error message 20009, severity 9:\nUnable to connect: Adaptive Server is unavailable or does not exist (192.168.1.228)\nNet-Lib error during Connection refused (111)\nDB-Lib error message 20009, severity 9:\nUnable to connect: Adaptive Server is unavailable or does not exist (192.168.1.228)\nNet-Lib error during Connection refused (111)\n')
[2024-09-09T15:45:16.822+0000] {taskinstance.py:1206} INFO - Marking task as FAILED. dag_id=product_etl_dag, task_id=extract_dimProudcts_load.get_src_tables, run_id=scheduled__2024-09-08T09:00:00+00:00, execution_date=20240908T090000, start_date=20240909T154455, end_date=20240909T154516
[2024-09-09T15:45:16.839+0000] {standard_task_runner.py:110} ERROR - Failed to execute job 26 for task extract_dimProudcts_load.get_src_tables ((20009, b'DB-Lib error message 20009, severity 9:\nUnable to connect: Adaptive Server is unavailable or does not exist (192.168.1.228)\nNet-Lib error during Connection refused (111)\nDB-Lib error message 20009, severity 9:\nUnable to connect: Adaptive Server is unavailable or does not exist (192.168.1.228)\nNet-Lib error during Connection refused (111)\n'); 182)
[2024-09-09T15:45:16.884+0000] {local_task_job_runner.py:243} INFO - Task exited with return code 1
[2024-09-09T15:45:16.904+0000] {taskinstance.py:3503} INFO - 0 downstream tasks scheduled from follow-on schedule check
[2024-09-09T15:45:16.908+0000] {local_task_job_runner.py:222} INFO - ::endgroup::
